Workbook
Name PIVOT: Data!#REF!
Name _AMO_SingleObject_328283544_ROM_F0.SEC2.Tabulate_1.SEC1.FTR.TXT1: #REF!
Name _AMO_SingleObject_328283544_ROM_F0.SEC2.Tabulate_1.SEC1.HDR.TXT1: #REF!
Name _AMO_SingleObject_328283544_ROM_F0.SEC2.Tabulate_1.SEC1.FTR.TXT2: #REF!
Name _AMO_SingleObject_328283544_ROM_F0.SEC2.Tabulate_1.SEC1.HDR.TXT2: #REF!
Name PIVOT2: #REF!
Name _AMO_SingleObject_328283544_ROM_F0.SEC2.Tabulate_1.SEC1.BDY.Cross_tabular_summary_report_Table_1: #REF!

Sheet Profile
A1: 2022 Hospital Discharge Summary Report
A4: Profile Characteristics (Individual Hospital Information will appear only if one hospital is selected)
A6: OSHPD Facility No. | B6: =IF($F$21=1,Pivot!B11,"") -> #REF!
A7: Hospital Name | B7: =IF($F$21=1,VLOOKUP($B$6,Data!A1:EP445,4,FALSE),IF(A1="(All)","",)) -> #REF!
A8: County | B8: =IF($F$21=1,VLOOKUP($B$6,Data!A1:EP445,3,FALSE),IF(Pivot!A3="(All)","",)) -> #REF!
A9: Address | B9: =IF($F$21=1,VLOOKUP($B$6,Data!A1:EP445,5,FALSE),"") -> #REF!
A10: City | B10: =IF($F$21=1,VLOOKUP($B$6,Data!A1:EP445,6,FALSE),"") -> #REF!
A11: ZIP Code | B11: =IF($F$21=1,VLOOKUP($B$6,Data!A1:EP445,7,FALSE),"") -> #REF!
A12: Type of Control | B12: =IF($F$21=1,VLOOKUP($B$6,Data!A1:EP445,8,FALSE),IF(Pivot!A2="(All)"," ",)) -> #REF!
A13: Teaching/Rural | B13: =IF($F$21=1,VLOOKUP($B$6,Data!A1:EP445,9,FALSE),IF(Pivot!A5="(All)","",)) -> #REF!
A14: Licensed Bed Size | B14: =IF($F$21=1,VLOOKUP($B$6,Data!A1:EP445,10,FALSE),IF(Pivot!A4="(All)","",)) -> #REF!
A15: Senate District | B15: =IF($F$21=1,VLOOKUP($B$6,Data!A1:EP445,11,FALSE),IF(Pivot!A6="(All)","",)) -> #REF!
A16: Assembly District | B16: =IF($F$21=1,VLOOKUP($B$6,Data!A1:EP445,12,FALSE),IF(Pivot!A7="(All)","",)) -> #REF!
A17: MSSA Designation | B17: =IF($F$21=1,VLOOKUP($B$6,Data!A1:EP445,14,FALSE),IF(Pivot!B1="(All)","",)) -> #REF!
A18: MSSA Name | B18: =IF($F$21=1,VLOOKUP($B$6,Data!A1:EP445,13,FALSE),IF(Pivot!B2="(All)","", )) -> #REF! | K18: Source: 2022 California Patient Discharge Data
A20: TYPE OF CARE | B20: # | C20: % | E20: DISCHARGES/DAYS | F20: # | I20: EXPECTED PAYER SOURCE | J20: # | K20: %
A21: Acute | B21: =GETPIVOTDATA("Sum of TOC_Acute",Pivot!$A$8) -> #REF! | C21: =B21/$B$27 -> #REF! | E21: Number of Hospital Reports | F21: =GETPIVOTDATA("Count of oshpd_id",Pivot!$A$8) -> #REF! | I21: Medi-Cal | J21: =GETPIVOTDATA("Sum of Payer_Medi_Cal",Pivot!$A$8) -> #REF! | K21: =J21/$J$31 -> #REF!
A22: Chemical Dependency | B22: =GETPIVOTDATA("Sum of TOC_Chem_Dep",Pivot!$A$8) -> #REF! | C22: =B22/$B$27 -> #REF! | E22: Number of Discharges | F22: =B27 -> #REF! | I22: Medicare | J22: =GETPIVOTDATA("Sum of Payer_Medicare",Pivot!$A$8) -> #REF! | K22: =J22/$J$31 -> #REF!
A23: Physical Rehabilitation | B23: =GETPIVOTDATA("Sum of TOC_Rehab",Pivot!$A$8) -> #REF! | C23: =B23/$B$27 -> #REF! | E23: Number of Discharge Days | F23: =GETPIVOTDATA("Sum of Dsch_Days",Pivot!$A$8) -> #REF! | I23: Private Coverage | J23: =GETPIVOTDATA("Sum of Payer_Priv_Coverage",Pivot!$A$8) -> #REF! | K23: =J23/$J$31 -> #REF!
A24: Psychiatric | B24: =GETPIVOTDATA("Sum of TOC_Psych",Pivot!$A$8) -> #REF! | C24: =B24/$B$27 -> #REF! | E24: Average Length of Stay (Days) | F24: =F23/F22 -> #REF! | I24: Self Pay | J24: =GETPIVOTDATA("Sum of Payer_Self_Pay",Pivot!$A$8) -> #REF! | K24: =J24/$J$31 -> #REF!
A25: Skilled Nursing/Intermediate Care | B25: =GETPIVOTDATA("Sum of TOC_SN_IC",Pivot!$A$8) -> #REF! | C25: =B25/$B$27 -> #REF! | I25: Workers' Compensation | J25: =GETPIVOTDATA("Sum of Payer_Workers_Comp",Pivot!$A$8) -> #REF! | K25: =J25/$J$31 -> #REF!
A26: Unknown/Blank/Invalid | B26: =GETPIVOTDATA("Sum of TOC_Unknown",Pivot!$A$8) -> #REF! | C26: =B26/$B$27 -> #REF! | I26: County Indigent Programs | J26: =GETPIVOTDATA("Sum of Payer_County_Indigent_Prog",Pivot!$A$8) -> #REF! | K26: =J26/$J$31 -> #REF!
B27: =SUM(B21:B26) -> #REF! | C27: =SUM(C21:C26) -> #REF! | E27: DNR ORDERS | F27: # | G27: % | I27: Other Government | J27: =GETPIVOTDATA("Sum of Payer_Other_Government",Pivot!$A$8) -> #REF! | K27: =J27/$J$31 -> #REF!
E28: Yes | F28: =GETPIVOTDATA("Sum of DNR_Yes",Pivot!$A$8) -> #REF! | G28: =F28/$F$31 -> #REF! | I28: Other Indigent | J28: =GETPIVOTDATA("Sum of Payer_Other_Indigent",Pivot!$A$8) -> #REF! | K28: =J28/$J$31 -> #REF!
E29: No | F29: =GETPIVOTDATA("Sum of DNR_No",Pivot!$A$8) -> #REF! | G29: =F29/$F$31 -> #REF! | I29: Other Payer | J29: =GETPIVOTDATA("Sum of Payer_Other_Payer",Pivot!$A$8) -> #REF! | K29: =J29/$J$31 -> #REF!
E30: Invalid | F30: =GETPIVOTDATA("Sum of DNR_Unknown",Pivot!$A$8) -> #REF! | G30: =F30/$F$31 -> #REF! | I30: Unknown/Blank/Invalid | J30: =GETPIVOTDATA("Sum of Payer_Unknown",Pivot!$A$8) -> #REF! | K30: =J30/$J$31 -> #REF!
F31: =SUM(F28:F30) -> #REF! | G31: =SUM(G28:G30) -> #REF! | J31: =SUM(J21:J30) -> #REF! | K31: =SUM(K21:K30) -> #REF!
A35: AGE GROUPS (at discharge) | B35: # | C35: % | E35: RACE | F35: # | G35: % | I35: PATIENT ZIP CODE GROUP | J35: # | K35: %
A36: 0 - 9 | B36: =GETPIVOTDATA("Sum of Age_0_09",Pivot!$A$9) -> 527704 | C36: =B36/$B$46 -> #REF! | E36: American Indian/Alaska Native | F36: =GETPIVOTDATA("Sum of racegrp_aman",Pivot!$A$9) -> 14414 | G36: =F36/$F$44 -> 0.0040000877 | I36: California Resident | J36: =GETPIVOTDATA("Sum of Zip_CA_Resident",Pivot!$A$9) -> 3442534 | K36: =J36/J$41 -> 0.9553516
A37: 10 - 19 | B37: =GETPIVOTDATA("Sum of Age_10_19",Pivot!$A$8) -> #REF! | C37: =B37/$B$46 -> #REF! | E37: Asian | F37: =GETPIVOTDATA("Sum of RaceGrp_Asian",Pivot!$A$9) -> 335529 | G37: =F37/$F$44 -> 0.093114016 | I37: Homeless* | J37: =GETPIVOTDATA("Sum of Zip_Homeless",Pivot!$A$9) -> 116580 | K37: =J37/J$41 -> 0.032352589
A38: 20 - 29 | B38: =GETPIVOTDATA("Sum of Age_20_29",Pivot!$A$8) -> #REF! | C38: =B38/$B$46 -> #REF! | E38: Black or African American | F38: =GETPIVOTDATA("Sum of RaceGrp_Black",Pivot!$A$9) -> 304186 | G38: =F38/$F$44 -> 0.084415893 | I38: Out of State | J38: =GETPIVOTDATA("Sum of Zip_Out_of_State",Pivot!$A$9) -> 33829 | K38: =J38/J$41 -> 0.0093880232
A39: 30 - 39 | B39: =GETPIVOTDATA("Sum of Age_30_39",Pivot!$A$8) -> #REF! | C39: =B39/$B$46 -> #REF! | E39: Multiracial | F39: =GETPIVOTDATA("Sum of racegrp_multirace",Pivot!$A$9) -> 66333 | G39: =F39/$F$44 -> 0.01840834 | I39: Does Not Reside in US | J39: =GETPIVOTDATA("Sum of Zip_Foreign",Pivot!$A$9) -> 4595 | K39: =J39/J$41 -> 0.0012751771
A40: 40 - 49 | B40: =GETPIVOTDATA("Sum of Age_40_49",Pivot!$A$8) -> #REF! | C40: =B40/$B$46 -> #REF! | E40: Native Hawaiian or Other Pacific Islander | F40: =GETPIVOTDATA("Sum of racegrp_nhpi",Pivot!$A$9) -> 22343 | G40: =F40/$F$44 -> 0.0062004967 | I40: Unknown/Blank/Invalid | J40: =GETPIVOTDATA("Sum of Zip_Unk_Inv_Bl",Pivot!$A$9) -> 5883 | K40: =J40/J$41 -> 0.0016326152
A41: 50 - 59 | B41: =GETPIVOTDATA("Sum of Age_50_59",Pivot!$A$8) -> #REF! | C41: =B41/$B$46 -> #REF! | E41: White | F41: =GETPIVOTDATA("Sum of RaceGrp_White",Pivot!$A$9) -> 1996646 | G41: =F41/$F$44 -> 0.55409734 | J41: =SUM(J36:J40) -> 3603421 | K41: =SUM(K36:K40) -> 1
A42: 60 - 69 | B42: =GETPIVOTDATA("Sum of Age_60_69",Pivot!$A$8) -> #REF! | C42: =B42/$B$46 -> #REF! | E42: Other Race | F42: =GETPIVOTDATA("Sum of RaceGrp_Other",Pivot!$A$9) -> 788243 | G42: =F42/$F$44 -> 0.21874852
A43: 70 - 79 | B43: =GETPIVOTDATA("Sum of Age_70_79",Pivot!$A$8) -> #REF! | C43: =B43/$B$46 -> #REF! | E43: Unknown/Blank/Invalid/Masked | F43: =GETPIVOTDATA("Sum of racegrp_unknown",Pivot!$A$9) -> 75727 | G43: =F43/$F$44 -> 0.021015307 | I43: * For definition, please see 'Instructions & Footnotes' tab
A44: 80+ | B44: =GETPIVOTDATA("Sum of Age_80_",Pivot!$A$8) -> #REF! | C44: =B44/$B$46 -> #REF! | F44: =SUM(F36:F43) -> 3603421 | G44: =SUM(G36:G43) -> 1
A45: Unknown/Blank/Invalid/Masked | B45: =GETPIVOTDATA("Sum of Age_Other_Unknown",Pivot!$A$9) -> 1225 | C45: =B45/$B$46 -> #REF!
B46: =SUM(B36:B45) -> #REF! | C46: =SUM(C36:C45) -> #REF!
E47: ETHNICITY | F47: # | G47: % | I47: SEX | J47: # | K47: %
...

Sheet Pivot
D3: Make your selection here
D146: This Excel pivot table uses the California Patient Discharge Database for January 1, 2022 to December 31, 2022. It is a fast and simple way to aggregate and display data.
D149: Select your variables above using the pulldown arrows. You can choose a specific hospital or county, or create a custom aggregation. To get Statewide totals, select "All" for all fields. When done, click on the "PROFILE" worksheet to see your results.
D153: Note: Avoid changing the worksheets as they contain many links, formulas and custom formats.
D156: **No adjustments have been made to the data for any hospitals with reporting modifications, non-compliances, data anomalies, or shortened report periods due to facility openings, closures, or consolidations. The data is aggregated at the facility level. Therefore, it does not contain individually identifiable health information.

Sheet Data
A1: oshpd_id9 | B1: OSHPD_ID | C1: COUNTY | D1: FACILITY_NAME | E1: ADDRESS | F1: CITY | G1: DBA_ZIP_CODE | H1: CONTROL_TYPE_DESC | I1: teach_rural | J1: licensed_bed_size | K1: senate_district_desc | L1: assembly_district_desc | M1: mssa_name | N1: mssa_designation | O1: TOC_Acute | P1: TOC_SN_IC | Q1: TOC_Psych | R1: TOC_Chem_Dep | S1: TOC_Rehab | T1: TOC_Unknown | U1: Sex_Male | V1: Sex_Female | W1: Sex_Other_Unknown | X1: Age_0_09 | Y1: Age_10_19 | Z1: Age_20_29 | AA1: Age_30_39 | AB1: Age_40_49 | AC1: Age_50_59 | AD1: Age_60_69 | AE1: Age_70_79 | AF1: Age_80_ | AG1: Age_Other_Unknown | AH1: eth_Hispanic | AI1: eth_NonHispanic | AJ1: eth_Other_Unknown | AK1: racegrp_aman | AL1: racegrp_asian | AM1: racegrp_nhpi | AN1: racegrp_black | AO1: racegrp_white | AP1: racegrp_unknown | AQ1: racegrp_other | AR1: racegrp_multirace | AS1: Admt_Non_HCF | AT1: Admt_Clinic_Dr | AU1: Admt_Hosp_Dif | AV1: Admt_SNF_ICF_ALF | AW1: Admt_Another_HCF | AX1: Admt_DistinctPartXfer | AY1: Admt_Amb_Surgery | AZ1: Admt_HospiceFacility | BA1: Admt_Court_LE | BB1: Admt_NA | BC1: Admt_Newborn | BD1: admt_disaster_care_site | BE1: Route_Your_ER | BF1: Route_Another_ER | BG1: Route_No_ER | BH1: Route_NA | BI1: dsch_days | BJ1: Adm_Emergency | BK1: Adm_Urgent | BL1: Adm_Elective | BM1: Adm_Newborn | BN1: Adm_Trauma | BO1: Adm_NA | BP1: disp_Routine | BQ1: disp_Acute_Care | BR1: disp_Rehab | BS1: disp_SN_IC_Care | BT1: disp_Residential_Care | BU1: disp_Prison_Jail | BV1: disp_Against_Medical_Advice | BW1: disp_Died | BX1: disp_Home_Health_Service | BY1: disp_Disaster_Care_Site | BZ1: disp_Childrens_or_Cancer | CA1: disp_Hospice_Care | CB1: disp_Psychiatric_Care | CC1: disp_CAH | CD1: disp_Not_Defined_Elsewhere | CE1: disp_Other | CF1: disp_Invalid_Blank | CG1: DNR_Yes | CH1: DNR_No | CI1: DNR_Unknown | CJ1: Payer_Medicare | CK1: Payer_Medi_Cal | CL1: Payer_Priv_Coverage | CM1: Payer_Workers_Comp | CN1: Payer_County_Indigent_Prog | CO1: Payer_Other_Government | CP1: Payer_Other_Indigent | CQ1: Payer_Self_Pay | CR1: Payer_Other_Payer | CS1: Payer_Unknown | CT1: dx_Infectious | CU1: dx_Neoplasms | CV1: dx_Diseases_of_the_Blood | CW1: dx_Endocrine | CX1: dx_MentalHealth | CY1: dx_Nervous_System | CZ1: dx_Eye | DA1: dx_Ear | DB1: dx_Circulatory | DC1: dx_Respiratory | DD1: dx_Digestive | DE1: dx_Skin | DF1: dx_Musculoskeletal | DG1: dx_Genitourinary | DH1: dx_Pregnancy_Childbirth | DI1: dx_Certain_Perinatal_Conditions | DJ1: dx_Congenital | DK1: dx_Symptoms_Signs_NEC | DL1: dx_Injury_Poisoning | DM1: dx_Factors_Influencing_Health | DN1: dx_Other_Unknown | DO1: PR_Diagnostic_Therapeutic | DP1: PR_Obstetrical | DQ1: PR_Cardiovascular_System | DR1: PR_Digestive_System | DS1: PR_Ear | DT1: PR_Endocrine_System | DU1: PR_Eye | DV1: PR_Reproductive_System | DW1: PR_Hemic_Lymph_System | DX1: PR_Integumentary_System | DY1: PR_Musculoskeletal_System | DZ1: PR_Nervous_System | EA1: PR_Nose_Mouth_Pharynx | EB1: PR_Respiratory_System | EC1: PR_Urinary_System | ED1: PR_None | EE1: PR_No_Group_Assigned | EF1: Zip_Unk_Inv_Bl | EG1: Zip_Homeless | EH1: Zip_Foreign | EI1: Zip_Out_of_State | EJ1: Zip_CA_Resident
A2: 106010735 | B2: 010735 | C2: ALAMEDA | D2: ALAMEDA HOSPITAL | E2: 2070 CLINTON AVE | F2: ALAMEDA | G2: 94501 | H2: City or County | I2: NA | J2: 100-149 | K2: District 9 | L2: District 18 | M2: Alameda/Jack London Square/Oakland Inner Harbor | N2: Urban | O2: 2646 | P2: 130 | S2: 1 | T2: 1 | U2: 1409 | V2: 1368 | W2: 1 | Z2: 104 | AA2: 187 | AB2: 296 | AC2: 408 | AD2: 590 | AE2: 570 | AF2: 619 | AG2: 4 | AH2: 487 | AI2: 2230 | AJ2: 61 | AL2: 480 | AM2: 19 | AN2: 727 | AO2: 943 | AP2: 30 | AQ2: 513 | AR2: 66 | AS2: 1823 | AT2: 5 | AU2: 461 | AV2: 380 | AW2: 12 | AX2: 94 | BB2: 3 | BE2: 2116 | BF2: 327 | BG2: 335 | BI2: 85839 | BJ2: 2119 | BK2: 379 | BL2: 279 | BO2: 1 | BP2: 1166 | BQ2: 204 | BR2: 60 | BS2: 574 | BV2: 119 | BW2: 102 | BX2: 500 | CA2: 46 | CB2: 6 | CD2: 1 | CG2: 109 | CH2: 2669 | CJ2: 1478 | CK2: 973 | CL2: 204 | CM2: 1 | CN2: 48 | CO2: 19 | CQ2: 55 | CT2: 460 | CU2: 49 | CV2: 52 | CW2: 138 | CX2: 79 | CY2: 181 | CZ2: 4 | DA2: 6 | DB2: 470 | DC2: 272 | DD2: 343 | DE2: 73 | DF2: 135 | DG2: 151 | DK2: 128 | DL2: 217 | DM2: 17 | DN2: 3 | DO2: 321 | DQ2: 221 | DR2: 168 | DU2: 1 | DV2: 19 | DX2: 39 | DY2: 123 | DZ2: 28 | EA2: 3 | EB2: 78 | EC2: 11 | ED2: 1743 | EE2: 23 | EF2: 1 | EG2: 141 | EI2: 27 | EJ2: 2609
A3: 106010739 | B3: 010739 | C3: ALAMEDA | D3: ALTA BATES SUMMIT MEDICAL CENTER-ALTA BATES CAMPUS | E3: 2450 ASHBY AVE | F3: BERKELEY | G3: 94705 | H3: Non-profit Corporation (incl. Church-related) | I3: NA | J3: 300-499 | K3: District 9 | L3: District 15 | M3: Albany/Berkeley East and North/Claremont/Cragmont/Forest Park/Rockridge/Temescal/Thousand Oaks | N3: Urban | O3: 15007 | U3: 5171 | V3: 9836 | X3: 4314 | Y3: 188 | Z3: 1720 | AA3: 3212 | AB3: 931 | AC3: 788 | AD3: 1104 | AE3: 1436 | AF3: 1314 | AH3: 4211 | AI3: 10314 | AJ3: 482 | AK3: 44 | AL3: 1873 | AM3: 389 | AN3: 3099 | AO3: 5072 | AP3: 320 | AQ3: 3941 | AR3: 269 | AS3: 9681 | AT3: 107 | AU3: 829 | AV3: 150 | AW3: 20 | AX3: 3 | AY3: 3 | AZ3: 1 | BB3: 1 | BC3: 4212 | BE3: 4758 | BF3: 547 | BG3: 9702 | BI3: 60441 | BJ3: 3534 | BK3: 4666 | BL3: 2595 | BM3: 4212 | BP3: 11358 | BQ3: 274 | BR3: 118 | BS3: 922 | BT3: 40 | BU3: 2 | BV3: 260 | BW3: 189 | BX3: 1590 | BZ3: 22 | CA3: 122 | CB3: 101 | CD3: 9 | CG3: 645 | CH3: 14362 | CJ3: 3074 | CK3: 6095 | CL3: 5174 | CM3: 12 | CO3: 396 | CQ3: 247 | CR3: 9 | CT3: 1322 | CU3: 241 | CV3: 139 | CW3: 269 | CX3: 128 | CY3: 222 | CZ3: 11 | DA3: 15 | DB3: 773 | DC3: 277 | DD3: 801 | DE3: 161 | DF3: 562 | DG3: 317 | DH3: 4719 | DI3: 4309 | DJ3: 6 | DK3: 136 | DL3: 584 | DM3: 15 | DO3: 1265 | DP3: 4209 | DQ3: 401 | DR3: 698 | DS3: 3 | DT3: 5 | DU3: 4 | DV3: 227 | DW3: 17 | DX3: 189 | DY3: 663 | DZ3: 247 | EA3: 33 | EB3: 167 | EC3: 122 | ED3: 6484 | EE3: 273 | EF3: 32 | EG3: 381 | EH3: 6 | EI3: 69 | EJ3: 14519
A4: 106010776 | B4: 010776 | C4: ALAMEDA | D4: UCSF BENIOFF CHILDREN'S HOSPITAL OAKLAND | E4: 747 52ND ST | F4: OAKLAND | G4: 94609 | H4: Non-profit Corporation (incl. Church-related) | I4: Teaching | J4: 150-199 | K4: District 9 | L4: District 15 | M4: Oakland West Central | N4: Urban | O4: 7240 | S4: 92 | U4: 3962 | V4: 3369 | W4: 1 | X4: 4770 | Y4: 2379 | Z4: 179 | AG4: 4 | AH4: 3194 | AI4: 4075 | AJ4: 63 | AK4: 29 | AL4: 604 | AM4: 96 | AN4: 1053 | AO4: 1437 | AP4: 66 | AQ4: 3617 | AR4: 430 | AS4: 4553 | AT4: 869 | AU4: 1766 | AW4: 84 | AX4: 58 | AY4: 1 | BB4: 1 | BE4: 5028 | BF4: 123 | BG4: 2181 | BI4: 41285 | BJ4: 3862 | BK4: 1711 | BL4: 1536 | BN4: 218 | BO4: 5 | BP4: 7059 | BQ4: 79 | BR4: 72 | BS4: 1 | BT4: 2 | BU4: 1 | BV4: 15 | BW4: 47 | BX4: 6 | BZ4: 5 | CA4: 5 | CB4: 40 | CG4: 24 | CH4: 7308 | CJ4: 18 | CK4: 3274 | CL4: 1919 | CO4: 2030 | CQ4: 82 | CR4: 9 | CT4: 630 | CU4: 202 | CV4: 253 | CW4: 326 | CX4: 79 | CY4: 568 | CZ4: 24 | DA4: 23 | DB4: 65 | DC4: 1353 | DD4: 757 | DE4: 149 | DF4: 294 | DG4: 209 | DI4: 410 | DJ4: 405 | DK4: 243 | DL4: 924 | DM4: 416 | DN4: 2 | DO4: 1311 | DQ4: 209 | DR4: 693 | DS4: 30 | DT4: 14 | DU4: 16 | DV4: 62 | DW4: 60 | DX4: 154 | DY4: 518 | DZ4: 338 | EA4: 199 | EB4: 94 | EC4: 31 | ED4: 3415 | EE4: 188 | EG4: 22 | EH4: 1 | EI4: 72 | EJ4: 7237
A5: 106010844 | B5: 010844 | C5: ALAMEDA | D5: ALTA BATES SUMMIT MEDICAL CENTER-HERRICK CAMPUS | E5: 2001 DWIGHT WAY | F5: BERKELEY | G5: 94704 | H5: Non-profit Corporation (incl. Church-related) | I5: Teaching | J5: 50-99 | K5: District 9 | L5: District 15 | M5: Berkeley South and West/Emeryville/Oakland Northwest | N5: Urban | Q5: 1609 | U5: 629 | V5: 980 | Y5: 532 | Z5: 324 | AA5: 241 | AB5: 159 | AC5: 120 | AD5: 140 | AE5: 60 | AF5: 33 | AH5: 194 | AI5: 1350 | AJ5: 65 | AK5: 11 | AL5: 153 | AM5: 21 | AN5: 323 | AO5: 800 | AP5: 43 | AQ5: 193 | AR5: 65 | AS5: 429 | AT5: 9 | AU5: 1076 | AV5: 3 | AW5: 12 | AX5: 80 | BF5: 953 | BG5: 656 | BI5: 16229 | BJ5: 6 | BK5: 1593 | BL5: 10 | BP5: 1384 | BQ5: 38 | BR5: 5 | BS5: 25 | BT5: 100 | BU5: 6 | BV5: 29 | BX5: 1 | BZ5: 1 | CB5: 8 | CD5: 12 | CG5: 1 | CH5: 1608 | CJ5: 312 | CK5: 637 | CL5: 600 | CM5: 2 | CO5: 23 | CQ5: 34 | CR5: 1 | CT5: 1 | CX5: 1600 | DN5: 8 | DO5: 302 | DQ5: 1 | DR5: 2 | DX5: 2 | DY5: 1 | EA5: 1 | ED5: 1265 | EE5: 35 | EF5: 5 | EG5: 270 | EI5: 17 | EJ5: 1317
A6: 106010846 | B6: 010846 | C6: ALAMEDA | D6: HIGHLAND HOSPITAL | E6: 1411 E 31ST ST | F6: OAKLAND | G6: 94602 | H6: City or County | I6: Teaching | J6: 200-299 | K6: District 9 | L6: District 18 | M6: Oakland West Central | N6: Urban | O6: 14681 | P6: 87 | Q6: 2479 | S6: 566 | T6: 11 | U6: 9475 | V6: 8345 | W6: 4 | X6: 1439 | Y6: 302 | Z6: 2413 | AA6: 2851 | AB6: 2151 | AC6: 2719 | AD6: 3083 | AE6: 1758 | AF6: 1104 | AG6: 4 | AH6: 5291 | AI6: 12348 | AJ6: 185 | AK6: 61 | AL6: 1914 | AM6: 186 | AN6: 6297 | AO6: 3048 | AP6: 120 | AQ6: 5733 | AR6: 465 | AS6: 12615 | AT6: 637 | AU6: 1380 | AV6: 358 | AW6: 198 | AX6: 906 | AY6: 10 | BA6: 105 | BB6: 227 | BC6: 1388 | BE6: 10805 | BF6: 26 | BG6: 6979 | BH6: 14 | BI6: 133268 | BJ6: 8981 | BK6: 4053 | BL6: 1919 | BM6: 1388 | BN6: 1460 | BO6: 23 | BP6: 11568 | BQ6: 822 | BR6: 333 | BS6: 1586 | BU6: 325 | BV6: 725 | BW6: 399 | BX6: 1338 | BZ6: 28 | CA6: 121 | CB6: 221 | CD6: 358 | CG6: 668 | CH6: 17155 | CI6: 1 | CJ6: 4991 | CK6: 11147 | CL6: 895 | CM6: 58 | CN6: 238 | CO6: 152 | CQ6: 343 | CT6: 1502 | CU6: 552 | CV6: 115 | CW6: 770 | CX6: 2950 | CY6: 477 | CZ6: 32 | DA6: 14 | DB6: 1681 | DC6: 736 | DD6: 1393 | DE6: 291 | DF6: 374 | DG6: 592 | DH6: 1634 | DI6: 1438 | DJ6: 8 | DK6: 332 | DL6: 2680 | DM6: 249 | DN6: 4 | DO6: 2731 | DP6: 1476 | DQ6: 1211 | DR6: 1087 | DS6: 20 | DT6: 18 | DU6: 16 | DV6: 154 | DW6: 46 | DX6: 614 | DY6: 914 | DZ6: 400 | EA6: 85 | EB6: 291 | EC6: 209 | ED6: 8098 | EE6: 454 | EF6: 1 | EG6: 1937 | EH6: 3 | EI6: 95 | EJ6: 15788
A7: 106010887 | B7: 010887 | C7: ALAMEDA | D7: KINDRED HOSPITAL - SAN FRANCISCO BAY AREA | E7: 2800 BENEDICT DR | F7: SAN LEANDRO | G7: 94577 | H7: Investor - Limited Liability Company | I7: Teaching | J7: 50-99 | K7: District 9 | L7: District 18 | M7: Castro Valley Central and North/Oak Knoll/San Leandro Northeast/Sheffield Village/Union City East | N7: Urban | O7: 331 | U7: 209 | V7: 122 | AA7: 28 | AB7: 40 | AC7: 91 | AD7: 70 | AE7: 67 | AF7: 26 | AG7: 9 | AH7: 66 | AI7: 224 | AJ7: 41 | AL7: 53 | AN7: 63 | AO7: 99 | AP7: 7 | AQ7: 109 | AU7: 331 | BG7: 331 | BI7: 23259 | BL7: 331 | BP7: 10 | BQ7: 117 | BR7: 19 | BS7: 103 | BT7: 1 | BV7: 5 | BW7: 34 | BX7: 41 | CA7: 1 | CG7: 16 | CH7: 315 | CJ7: 77 | CK7: 163 | CL7: 83 | CM7: 2 | CO7: 6 | CT7: 11 | CU7: 1 | CW7: 2 | CY7: 1 | DB7: 5 | DC7: 230 | DD7: 10 | DE7: 15 | DF7: 13 | DG7: 10 | DL7: 22 | DM7: 11 | DO7: 145 | DQ7: 33 | DR7: 19 | DS7: 1 | DX7: 13 | DY7: 10 | EA7: 2 | EB7: 3 | EC7: 1 | ED7: 100 | EE7: 4 | EF7: 1 | EG7: 8 | EI7: 2 | EJ7: 320
A8: 106010937 | B8: 010937 | C8: ALAMEDA | D8: ALTA BATES SUMMIT MEDICAL CENTER | E8: 350 HAWTHORNE AVE | F8: OAKLAND | G8: 94609 | H8: Non-profit Corporation (incl. Church-related) | I8: Teaching | J8: 300-499 | K8: District 9 | L8: District 18 | M8: Dimond/Montclair/Oakland East/Oakmore/Piedmont/Piedmont Pines/Trestle Glen | N8: Urban | O8: 9656 | S8: 724 | U8: 5219 | V8: 5161 | Y8: 30 | Z8: 256 | AA8: 650 | AB8: 845 | AC8: 1437 | AD8: 2316 | AE8: 2470 | AF8: 2376 | AH8: 1129 | AI8: 9091 | AJ8: 160 | AK8: 23 | AL8: 1664 | AM8: 226 | AN8: 3786 | AO8: 3300 | AP8: 118 | AQ8: 1192 | AR8: 71 | AS8: 8563 | AT8: 129 | AU8: 1170 | AV8: 364 | AW8: 12 | AX8: 127 | AY8: 14 | AZ8: 1 | BE8: 7612 | BF8: 288 | BG8: 2480 | BI8: 63533 | BJ8: 5688 | BK8: 2611 | BL8: 2081 | BP8: 4267 | BQ8: 297 | BR8: 253 | BS8: 1517 | BT8: 73 | BU8: 1 | BV8: 266 | BW8: 382 | BX8: 3053 | BZ8: 1 | CA8: 261 | CB8: 8 | CD8: 1 | CG8: 1059 | CH8: 9321 | CJ8: 5512 | CK8: 2415 | CL8: 2131 | CM8: 24 | CO8: 141 | CQ8: 142 | CR8: 15 | CT8: 1825 | CU8: 617 | CV8: 213 | CW8: 688 | CX8: 116 | CY8: 376 | CZ8: 15 | DA8: 10 | DB8: 2828 | DC8: 492 | DD8: 989 | DE8: 89 | DF8: 372 | DG8: 513 | DH8: 14 | DJ8: 15 | DK8: 198 | DL8: 812 | DM8: 198 | DO8: 1555 | DQ8: 1740 | DR8: 1227 | DS8: 3 | DT8: 23 | DV8: 82 | DW8: 81 | DX8: 293 | DY8: 509 | DZ8: 98 | EA8: 22 | EB8: 332 | EC8: 134 | ED8: 4016 | EE8: 265 | EF8: 4 | EG8: 549 | EH8: 6 | EI8: 76 | EJ8: 9745
A9: 106010967 | B9: 010967 | C9: ALAMEDA | D9: ST. ROSE HOSPITAL | E9: 27200 CALAROGA AVE | F9: HAYWARD | G9: 94545 | H9: Non-profit Corporation (incl. Church-related) | I9: Teaching | J9: 150-199 | K9: District 10 | L9: District 20 | M9: San Leandro West/San Lorenzo West/Hayward West | N9: Urban | O9: 4209 | U9: 2084 | V9: 2125 | X9: 315 | Y9: 52 | Z9: 331 | AA9: 368 | AB9: 361 | AC9: 534 | AD9: 878 | AE9: 690 | AF9: 680 | AH9: 1346 | AI9: 2835 | AJ9: 28 | AL9: 879 | AM9: 140 | AN9: 612 | AO9: 1048 | AP9: 39 | AQ9: 1451 | AR9: 40 | AS9: 3206 | AT9: 37 | AU9: 152 | AV9: 489 | AW9: 3 | AZ9: 2 | BA9: 4 | BB9: 1 | BC9: 315 | BE9: 3260 | BF9: 51 | BG9: 898 | BI9: 17227 | BJ9: 3274 | BK9: 272 | BL9: 348 | BM9: 315 | BP9: 2424 | BQ9: 171 | BR9: 11 | BS9: 640 | BT9: 75 | BV9: 123 | BW9: 163 | BX9: 530 | BZ9: 5 | CA9: 50 | CB9: 17 | CG9: 277 | CH9: 3932 | CJ9: 1615 | CK9: 2125 | CL9: 348 | CM9: 6 | CO9: 14 | CP9: 26 | CQ9: 75 | CT9: 586 | CU9: 54 | CV9: 35 | CW9: 243 | CX9: 83 | CY9: 105 | CZ9: 3 | DA9: 9 | DB9: 794 | DC9: 283 | DD9: 514 | DE9: 57 | DF9: 209 | DG9: 248 | DH9: 352 | DI9: 315 | DK9: 115 | DL9: 197 | DM9: 6 | DN9: 1 | DO9: 728 | DP9: 309 | DQ9: 579 | DR9: 480 | DV9: 41 | DW9: 7 | DX9: 52 | DY9: 255 | DZ9: 13 | EA9: 12 | EB9: 45 | EC9: 25 | ED9: 1587 | EE9: 76 | EF9: 5 | EG9: 126 | EH9: 1 | EI9: 11 | EJ9: 4066
A10: 106010987 | B10: 010987 | C10: ALAMEDA | D10: WASHINGTON HOSPITAL - FREMONT | E10: 2000 MOWRY AVE | F10: FREMONT | G10: 94538 | H10: District | I10: Teaching | J10: 300-499 | K10: District 10 | L10: District 20 | M10: Fremont East/Niles/Union City Central | N10: Urban | O10: 11205 | P10: 302 | U10: 4981 | V10: 6526 | X10: 1639 | Y10: 46 | Z10: 433 | AA10: 1464 | AB10: 649 | AC10: 1000 | AD10: 1763 | AE10: 2008 | AF10: 2505 | AH10: 1483 | AI10: 9855 | AJ10: 169 | AK10: 13 | AL10: 5295 | AM10: 105 | AN10: 543 | AO10: 3352 | AP10: 152 | AQ10: 1818 | AR10: 229 | AS10: 7405 | AT10: 2109 | AV10: 399 | AW10: 68 | AZ10: 74 | BA10: 2 | BC10: 1450 | BE10: 7807 | BF10: 48 | BG10: 3652 | BI10: 58714 | BJ10: 7749 | BK10: 1400 | BL10: 906 | BM10: 1450 | BN10: 2 | BP10: 6596 | BQ10: 153 | BR10: 69 | BS10: 1460 | BW10: 408 | BX10: 2622 | BZ10: 6 | CA10: 160 | CB10: 22 | CC10: 3 | CD10: 5 | CE10: 2 | CF10: 1 | CG10: 1173 | CH10: 10334 | CJ10: 4961 | CK10: 2104 | CL10: 4170 | CM10: 56 | CO10: 57 | CQ10: 71 | CS10: 88 | CT10: 1386 | CU10: 342 | CV10: 47 | CW10: 474 | CX10: 95 | CY10: 178 | CZ10: 8 | DA10: 20 | DB10: 1821 | DC10: 770 | DD10: 1076 | DE10: 252 | DF10: 419 | DG10: 607 | DH10: 1532 | DI10: 1537 | DJ10: 9 | DK10: 55 | DL10: 837 | DM10: 38 | DN10: 4 | DO10: 2949 | DP10: 1433 | DQ10: 1218 | DR10: 850 | DS10: 6 | DT10: 18 | DV10: 95 | DW10: 26 | DX10: 220 | DY10: 743 | DZ10: 181 | EA10: 19 | EB10: 247 | EC10: 143 | ED10: 3108 | EE10: 251 | EF10: 11 | EG10: 149 | EH10: 30 | EI10: 59 | EJ10: 11258
A11: 106013687 | B11: 013687 | C11: ALAMEDA | D11: MPI CHEMICAL DEPENDENCY RECOVERY HOSPITAL | E11: 3012 SUMMIT ST | F11: OAKLAND | G11: 94609 | H11: Non-profit Corporation (incl. Church-related) | I11: Teaching | J11: 1-49 | K11: District 9 | L11: District 18 | M11: Dimond/Montclair/Oakland East/Oakmore/Piedmont/Piedmont Pines/Trestle Glen | N11: Urban | R11: 343 | U11: 221 | V11: 122 | Z11: 64 | AA11: 102 | AB11: 55 | AC11: 76 | AD11: 32 | AG11: 14 | AH11: 45 | AI11: 279 | AJ11: 19 | AL11: 17 | AN11: 40 | AO11: 227 | AP11: 29 | AQ11: 30 | AS11: 322 | AU11: 18 | AV11: 1 | AW11: 2 | BF11: 12 | BG11: 331 | BI11: 3747 | BK11: 17 | BL11: 326 | BP11: 304 | BQ11: 6 | BS11: 2 | BT11: 6 | BV11: 20 | BW11: 1 | CB11: 3 | CD11: 1 | CG11: 2 | CH11: 341 | CJ11: 4 | CK11: 1 | CL11: 304 | CO11: 27 | CQ11: 7 | CX11: 341 | DN11: 2 | DO11: 309 | ED11: 33 | EE11: 1 | EF11: 1 | EG11: 18 | EI11: 4 | EJ11: 320
A12: 106014034 | B12: 014034 | C12: ALAMEDA | D12: FREMONT HOSPITAL | E12: 39001 SUNDALE DR | F12: FREMONT | G12: 94538 | H12: Investor - Corporation | I12: Teaching | J12: 100-149 | K12: District 10 | L12: District 25 | M12: Centerville/Fremont West/Irvington/Newark East Central | N12: Urban | Q12: 5412 | U12: 2169 | V12: 3241 | W12: 2 | Y12: 2631 | Z12: 1118 | AA12: 706 | AB12: 461 | AC12: 312 | AD12: 135 | AE12: 47 | AG12: 2 | AH12: 828 | AI12: 4584 | AL12: 472 | AN12: 206 | AO12: 1455 | AP12: 29 | AQ12: 3250 | AS12: 63 | AU12: 4629 | AW12: 720 | BF12: 4631 | BG12: 781 | BI12: 42792 | BK12: 5412 | BP12: 5122 | BQ12: 14 | BT12: 64 | BU12: 1 | BV12: 205 | CE12: 6 | CH12: 5412 | CJ12: 516 | CK12: 1304 | CL12: 2575 | CM12: 1 | CO12: 1016 | CX12: 5404 | DN12: 8 | DO12: 776 | ED12: 4636 | EF12: 35 | EG12: 548 | EI12: 17 | EJ12: 4812
A13: 106014050 | B13: 014050 | C13: ALAMEDA | D13: STANFORD HEALTH CARE TRI-VALLEY | E13: 5555 W LAS POSITAS BLVD | F13: PLEASANTON | G13: 94588 | H13: Non-profit Corporation (incl. Church-related) | I13: Teaching | J13: 150-199 | K13: District 7 | L13: District 16 | M13: Dublin/Pleasanton/Santa Rita/Sunol | N13: Urban | O13: 8050 | U13: 3449 | V13: 4600 | W13: 1 | X13: 1353 | Y13: 34 | Z13: 400 | AA13: 1305 | AB13: 486 | AC13: 701 | AD13: 1014 | AE13: 1329 | AF13: 1428 | AH13: 993 | AI13: 6986 | AJ13: 71 | AK13: 31 | AL13: 1550 | AM13: 41 | AN13: 319 | AO13: 3673 | AP13: 48 | AQ13: 2213 | AR13: 175 | AS13: 6147 | AT13: 162 | AU13: 225 | AV13: 163 | AW13: 7 | AX13: 1 | AY13: 6 | AZ13: 3 | BA13: 33 | BC13: 1303 | BE13: 4280 | BF13: 34 | BG13: 3736 | BI13: 35608 | BJ13: 4441 | BK13: 256 | BL13: 2050 | BM13: 1303 | BP13: 4978 | BQ13: 173 | BR13: 40 | BS13: 986 | BU13: 36 | BW13: 244 | BX13: 1430 | BZ13: 1 | CA13: 149 | CB13: 9 | CE13: 4 | CG13: 491 | CH13: 7559 | CJ13: 3120 | CK13: 788 | CL13: 3193 | CM13: 34 | CO13: 96 | CQ13: 179 | CR13: 640 | CT13: 917 | CU13: 223 | CV13: 42 | CW13: 393 | CX13: 86 | CY13: 118 | CZ13: 4 | DA13: 6 | DB13: 1185 | DC13: 379 | DD13: 742 | DE13: 66 | DF13: 312 | DG13: 283 | DH13: 1376 | DI13: 1347 | DJ13: 11 | DK13: 59 | DL13: 492 | DM13: 9 | DO13: 875 | DP13: 1268 | DQ13: 932 | DR13: 741 | DT13: 1 | DV13: 56 | DW13: 23 | DX13: 102 | DY13: 472 | DZ13: 82 | EA13: 11 | EB13: 219 | EC13: 99 | ED13: 3008 | EE13: 161 | EG13: 90 | EH13: 5 | EI13: 64 | EJ13: 7891
A14: 106014132 | B14: 014132 | C14: ALAMEDA | D14: KAISER FOUNDATION HOSPITAL - FREMONT | E14: 39400 PASEO PADRE PKWY | F14: FREMONT | G14: 94538 | H14: Non-profit Corporation (incl. Church-related) | I14: Teaching | J14: 100-149 | K14: District 10 | L14: District 25 | M14: Fremont East/Niles/Union City Central | N14: Urban | O14: 4364 | Q14: 272 | U14: 2337 | V14: 2299 | Y14: 24 | Z14: 138 | AA14: 210 | AB14: 308 | AC14: 564 | AD14: 865 | AE14: 1052 | AF14: 1472 | AG14: 3 | AH14: 607 | AI14: 4023 | AJ14: 6 | AL14: 1385 | AM14: 33 | AN14: 330 | AO14: 2234 | AP14: 29 | AQ14: 625 | AS14: 3723 | AT14: 117 | AU14: 427 | AV14: 200 | AW14: 166 | AX14: 1 | AY14: 1 | BB14: 1 | BE14: 4064 | BF14: 243 | BG14: 329 | BI14: 23540 | BJ14: 565 | BK14: 3986 | BL14: 85 | BP14: 1977 | BQ14: 285 | BR14: 29 | BS14: 524 | BT14: 1 | BV14: 48 | BW14: 216 | BX14: 1346 | CA14: 172 | CB14: 29 | CD14: 3 | CE14: 6 | CG14: 869 | CH14: 3767 | CJ14: 2957 | CK14: 218 | CL14: 1391 | CM14: 16 | CO14: 2 | CQ14: 52 | CT14: 1292 | CU14: 106 | CV14: 49 | CW14: 236 | CX14: 331 | CY14: 106 | CZ14: 1 | DA14: 5 | DB14: 886 | DC14: 274 | DD14: 510 | DE14: 69 | DF14: 51 | DG14: 233 | DH14: 15 | DJ14: 1 | DK14: 135 | DL14: 322 | DM14: 14 | DO14: 1222 | DQ14: 318 | DR14: 538 | DS14: 2 | DT14: 6 | DV14: 19 | DW14: 11 | DX14: 106 | DY14: 200 | DZ14: 42 | EA14: 20 | EB14: 89 | EC14: 185 | ED14: 1675 | EE14: 203 | EG14: 55 | EI14: 15 | EJ14: 4566
A15: 106014207 | B15: 014207 | C15: ALAMEDA | D15: TELECARE HERITAGE PSYCHIATRIC HEALTH FACILITY | E15: 2633 E 27TH ST | F15: OAKLAND | G15: 94601 | H15: Investor - Corporation | I15: Teaching | J15: 1-49 | K15: District 9 | L15: District 18 | M15: Oakland West Central | N15: Urban | Q15: 1149 | U15: 523 | V15: 626 | Y15: 115 | Z15: 388 | AA15: 239 | AB15: 164 | AC15: 122 | AD15: 86 | AE15: 32 | AG15: 3 | AH15: 218 | AI15: 863 | AJ15: 68 | AL15: 86 | AN15: 164 | AO15: 517 | AP15: 33 | AQ15: 349 | AS15: 807 | AU15: 314 | AW15: 25 | BB15: 3 | BG15: 1149 | BI15: 6275 | BK15: 1149 | BP15: 1024 | BQ15: 16 | BS15: 2 | BT15: 57 | BU15: 2 | BV15: 48 | CH15: 1149 | CJ15: 202 | CK15: 47 | CL15: 885 | CQ15: 1 | CR15: 14 | CX15: 1149 | ED15: 1149 | EF15: 4 | EG15: 3 | EJ15: 1142
A16: 106014226 | B16: 014226 | C16: ALAMEDA | D16: TELECARE WILLOW ROCK CENTER | E16: 2050 FAIRMONT DR | F16: SAN LEANDRO | G16: 94578 | H16: Investor - Corporation | I16: Teaching | J16: 1-49 | K16: District 10 | L16: District 20 | M16: Castro Valley Central and North/Oak Knoll/San Leandro Northeast/Sheffield Village/Union City East | N16: Urban | Q16: 447 | U16: 168 | V16: 279 | Y16: 447 | AH16: 135 | AI16: 281 | AJ16: 31 | AL16: 14 | AN16: 80 | AO16: 148 | AP16: 16 | AQ16: 189 | AS16: 334 | AT16: 3 | AU16: 102 | AW16: 4 | BA16: 2 | BB16: 2 | BG16: 447 | BI16: 2385 | BK16: 447 | BP16: 431 | BQ16: 1 | BT16: 2 | BU16: 1 | BV16: 6 | CA16: 6 | CH16: 447 | CK16: 5 | CL16: 229 | CN16: 208 | CP16: 1 | CR16: 4 | CX16: 447 | ED16: 447 | EJ16: 447
A17: 106014233 | B17: 014233 | C17: ALAMEDA | D17: EDEN MEDICAL CENTER | E17: 20103 LAKE CHABOT RD | F17: CASTRO VALLEY | G17: 94546 | H17: Non-profit Corporation (incl. Church-related) | I17: Teaching | J17: 100-149 | K17: District 10 | L17: District 20 | M17: Castro Valley Central and North/Oak Knoll/San Leandro Northeast/Sheffield Village/Union City East | N17: Urban | O17: 9600 | U17: 4361 | V17: 5239 | X17: 1194 | Y17: 106 | Z17: 713 | AA17: 1269 | AB17: 652 | AC17: 961 | AD17: 1469 | AE17: 1551 | AF17: 1685 | AH17: 2424 | AI17: 7017 | AJ17: 159 | AK17: 29 | AL17: 1478 | AM17: 517 | AN17: 1429 | AO17: 4083 | AP17: 120 | AQ17: 1797 | AR17: 147 | AS17: 7659 | AT17: 71 | AU17: 200 | AV17: 449 | AW17: 20 | AY17: 3 | BA17: 5 | BC17: 1193 | BE17: 6574 | BF17: 77 | BG17: 2949 | BI17: 44615 | BJ17: 4183 | BK17: 1950 | BL17: 1016 | BM17: 1193 | BN17: 1258 | BP17: 5042 | BQ17: 413 | BR17: 162 | BS17: 1522 | BT17: 69 | BU17: 16 | BV17: 188 | BW17: 339 | BX17: 1544 | BZ17: 1 | CA17: 258 | CB17: 43 | CD17: 3 | CG17: 725 | CH17: 8875 | CJ17: 3597 | CK17: 2374 | CL17: 3229 | CM17: 62 | CO17: 150 | CQ17: 171 | CR17: 17 | CT17: 1264 | CU17: 259 | CV17: 114 | CW17: 358 | CX17: 106 | CY17: 269 | CZ17: 13 | DA17: 9 | DB17: 1208 | DC17: 357 | DD17: 739 | DE17: 120 | DF17: 291 | DG17: 357 | DH17: 1253 | DI17: 1194 | DJ17: 3 | DK17: 140 | DL17: 1523 | DM17: 23 | DO17: 1233 | DP17: 1185 | DQ17: 526 | DR17: 713 | DS17: 5 | DT17: 6 | DU17: 12 | DV17: 116 | DW17: 36 | DX17: 313 | DY17: 729 | DZ17: 217 | EA17: 21 | EB17: 232 | EC17: 123 | ED17: 3958 | EE17: 175 | EF17: 10 | EG17: 254 | EH17: 6 | EI17: 52 | EJ17: 9278
A18: 106014326 | B18: 014326 | C18: ALAMEDA | D18: KAISER FOUNDATION HOSPITAL - OAKLAND/RICHMOND | E18: 275 W MACARTHUR BLVD | F18: OAKLAND | G18: 94611 | H18: Non-profit Corporation (incl. Church-related) | I18: Teaching | J18: 300-499 | K18: District 9 | L18: District 15 | M18: Dimond/Montclair/Oakland East/Oakmore/Piedmont/Piedmont Pines/Trestle Glen | N18: Urban | O18: 23461 | U18: 10314 | V18: 13146 | W18: 1 | X18: 3847 | Y18: 903 | Z18: 1138 | AA18: 2870 | AB18: 1660 | AC18: 2190 | AD18: 3306 | AE18: 3946 | AF18: 3599 | AG18: 2 | AH18: 3946 | AI18: 19069 | AJ18: 446 | AK18: 83 | AL18: 3753 | AM18: 125 | AN18: 5756 | AO18: 8395 | AP18: 554 | AQ18: 4425 | AR18: 370 | AS18: 18889 | AT18: 145 | AU18: 1421 | AV18: 320 | AW18: 47 | AX18: 3 | AY18: 2 | BB18: 66 | BC18: 2563 | BD18: 5 | BE18: 12023 | BF18: 1042 | BG18: 10396 | BI18: 104645 | BJ18: 2664 | BK18: 14312 | BL18: 3916 | BM18: 2563 | BO18: 6 | BP18: 16734 | BQ18: 449 | BR18: 117 | BS18: 1817 | BT18: 6 | BV18: 260 | BW18: 689 | BX18: 2979 | BZ18: 2 | CA18: 296 | CB18: 49 | CC18: 2 | CD18: 38 | CE18: 23 | CG18: 2257 | CH18: 21204 | CJ18: 9437 | CK18: 2618 | CL18: 10950 | CM18: 18 | CO18: 125 | CQ18: 312 | CS18: 1 | CT18: 2823 | CU18: 1513 | CV18: 309 | CW18: 863 | CX18: 314 | CY18: 641 | CZ18: 32 | DA18: 30 | DB18: 3080 | DC18: 1385 | DD18: 1990 | DE18: 233 | DF18: 1317 | DG18: 658 | DH18: 2816 | DI18: 2684 | DJ18: 205 | DK18: 553 | DL18: 1374 | DM18: 641 | DO18: 6449 | DP18: 2567 | DQ18: 1542 | DR18: 2011 | DS18: 28 | DT18: 31 | DU18: 7 | DV18: 582 | DW18: 158 | DX18: 404 | DY18: 1702 | DZ18: 697 | EA18: 174 | EB18: 793 | EC18: 510 | ED18: 5204 | EE18: 602 | EF18: 23 | EG18: 239 | EI18: 61 | EJ18: 23138
A19: 106014337 | B19: 014337 | C19: ALAMEDA | D19: KAISER FOUNDATION HOSPITAL - SAN LEANDRO | E19: 2500 MERCED ST | F19: SAN LEANDRO | G19: 94577 | H19: Non-profit Corporation (incl. Church-related) | I19: Teaching | J19: 200-299 | K19: District 9 | L19: District 18 | M19: San Leandro West/San Lorenzo West/Hayward West | N19: Urban | O19: 15533 | U19: 5890 | V19: 9643 | X19: 3916 | Y19: 82 | Z19: 1372 | AA19: 3085 | AB19: 799 | AC19: 1023 | AD19: 1606 | AE19: 1819 | AF19: 1824 | AG19: 7 | AH19: 4116 | AI19: 11221 | AJ19: 196 | AK19: 72 | AL19: 4702 | AM19: 285 | AN19: 2025 | AO19: 4166 | AP19: 188 | AQ19: 3528 | AR19: 567 | AS19: 10460 | AT19: 153 | AU19: 498 | AV19: 344 | AW19: 255 | AX19: 1 | AZ19: 1 | BB19: 1 | BC19: 3819 | BD19: 1 | BE19: 6179 | BF19: 270 | BG19: 9084 | BI19: 53205 | BJ19: 602 | BK19: 9659 | BL19: 1453 | BM19: 3819 | BP19: 11024 | BQ19: 295 | BR19: 24 | BS19: 1036 | BV19: 76 | BW19: 361 | BX19: 2482 | CA19: 205 | CB19: 21 | CD19: 6 | CE19: 3 | CG19: 1222 | CH19: 14311 | CJ19: 4597 | CK19: 1247 | CL19: 9542 | CM19: 5 | CO19: 9 | CQ19: 133 | CT19: 2093 | CU19: 259 | CV19: 101 | CW19: 346 | CX19: 173 | CY19: 191 | CZ19: 4 | DA19: 6 | DB19: 1285 | DC19: 442 | DD19: 982 | DE19: 136 | DF19: 282 | DG19: 411 | DH19: 4047 | DI19: 3910 | DJ19: 6 | DK19: 152 | DL19: 656 | DM19: 49 | DN19: 2 | DO19: 4898 | DP19: 3797 | DQ19: 571 | DR19: 1123 | DS19: 6 | DT19: 1 | DU19: 3 | DV19: 879 | DW19: 17 | DX19: 206 | DY19: 715 | DZ19: 52 | EA19: 69 | EB19: 175 | EC19: 299 | ED19: 2412 | EE19: 310 | EF19: 3 | EG19: 69 | EI19: 26 | EJ19: 15435
A20: 106034002 | B20: 034002 | C20: AMADOR | D20: SUTTER AMADOR HOSPITAL | E20: 200 MISSION BLVD | F20: JACKSON | G20: 95642 | H20: Non-profit Corporation (incl. Church-related) | I20: Small/Rural | J20: 50-99 | K20: District 8 | L20: District 5 | M20: Ione/Jackson/Pine Grove/Sutter Creek | N20: Rural | O20: 2416 | U20: 1031 | V20: 1385 | X20: 239 | Y20: 16 | Z20: 147 | AA20: 185 | AB20: 107 | AC20: 209 | AD20: 423 | AE20: 535 | AF20: 555 | AH20: 213 | AI20: 2131 | AJ20: 72 | AK20: 32 | AL20: 11 | AN20: 18 | AO20: 2172 | AP20: 44 | AQ20: 98 | AR20: 41 | AS20: 2040 | AT20: 20 | AU20: 26 | AV20: 50 | AW20: 1 | AX20: 1 | AZ20: 1 | BA20: 45 | BB20: 1 | BC20: 231 | BE20: 1820 | BF20: 3 | BG20: 593 | BI20: 10181 | BJ20: 1391 | BK20: 517 | BL20: 277 | BM20: 231 | BP20: 1259 | BQ20: 135 | BR20: 8 | BS20: 284 | BT20: 4 | BU20: 49 | BV20: 52 | BW20: 57 | BX20: 494 | CA20: 66 | CB20: 3 | CC20: 1 | CD20: 4 | CG20: 230 | CH20: 2186 | CJ20: 1325 | CK20: 577 | CL20: 363 | CM20: 5 | CO20: 117 | CQ20: 29 | CT20: 563 | CU20: 17 | CV20: 17 | CW20: 83 | CX20: 37 | CY20: 60 | CZ20: 1 | DA20: 3 | DB20: 325 | DC20: 140 | DD20: 248 | DE20: 35 | DF20: 96 | DG20: 61 | DH20: 249 | DI20: 239 | DK20: 41 | DL20: 199 | DM20: 2 | DO20: 315 | DP20: 232 | DQ20: 62 | DR20: 182 | DU20: 1 | DV20: 6 | DW20: 3 | DX20: 31 | DY20: 200 | DZ20: 8 | EA20: 2 | EB20: 27 | EC20: 4 | ED20: 1228 | EE20: 115 | EF20: 3 | EG20: 26 | EH20: 2 | EI20: 15 | EJ20: 2370
A21: 106040802 | B21: 040802 | C21: BUTTE | D21: ORCHARD HOSPITAL | E21: 240 SPRUCE ST | F21: GRIDLEY | G21: 95948 | H21: Non-profit Corporation (incl. Church-related) | I21: Small/Rural | J21: 100-149 | K21: District 4 | L21: District 3 | M21: Biggs/East Biggs/Gridley | N21: Rural | O21: 327 | P21: 186 | U21: 263 | V21: 250 | AA21: 11 | AB21: 32 | AC21: 72 | AD21: 93 | AE21: 117 | AF21: 179 | AG21: 9 | AH21: 83 | AI21: 426 | AJ21: 4 | AO21: 421 | AP21: 19 | AQ21: 73 | AS21: 298 | AT21: 2 | AU21: 97 | AV21: 21 | AW21: 2 | AX21: 93 | BE21: 311 | BG21: 202 | BI21: 3660 | BK21: 329 | BL21: 184 | BP21: 249 | BQ21: 31 | BR21: 2 | BS21: 125 | BV21: 20 | BW21: 23 | BX21: 42 | BZ21: 1 | CA21: 9 | CC21: 11 | CG21: 431 | CH21: 82 | CJ21: 342 | CK21: 124 | CL21: 41 | CO21: 4 | CQ21: 2 | CT21: 104 | CU21: 13 | CW21: 39 | CX21: 14 | CY21: 21 | DA21: 1 | DB21: 85 | DC21: 69 | DD21: 22 | DE21: 18 | DF21: 29 | DG21: 17 | DK21: 18 | DL21: 54 | DM21: 9 | DO21: 21 | DQ21: 13 | DR21: 1 | DX21: 4 | DY21: 7 | ED21: 460 | EE21: 7 | EG21: 18 | EI21: 2 | EJ21: 493
A22: 106040937 | B22: 040937 | C22: BUTTE | D22: OROVILLE HOSPITAL | E22: 2767 OLIVE HWY | F22: OROVILLE | G22: 95966 | H22: Non-profit Corporation (incl. Church-related) | I22: Small/Rural | J22: 100-149 | K22: District 4 | L22: District 3 | M22: Oroville/Palermo/Thermalito | N22: Rural | O22: 11763 | P22: 419 | U22: 5761 | V22: 6421 | X22: 562 | Y22: 202 | Z22: 741 | AA22: 1067 | AB22: 1201 | AC22: 1834 | AD22: 2674 | AE22: 2192 | AF22: 1709 | AH22: 924 | AI22: 10778 | AJ22: 480 | AK22: 283 | AL22: 491 | AN22: 345 | AO22: 9813 | AP22: 156 | AQ22: 1022 | AR22: 72 | AS22: 11091 | AT22: 2 | AU22: 10 | AV22: 131 | AW22: 19 | AX22: 416 | AY22: 37 | BA22: 18 | BB22: 1 | BC22: 457 | BE22: 10054 | BG22: 2128 | BI22: 64812 | BJ22: 57 | BK22: 10412 | BL22: 1256 | BM22: 457 | BP22: 8468 | BQ22: 222 | BR22: 2 | BS22: 1140 | BT22: 77 | BU22: 65 | BV22: 1062 | BW22: 270 | BX22: 802 | CA22: 51 | CB22: 14 | CE22: 9 | CG22: 465 | CH22: 11717 | CJ22: 5634 | CK22: 4893 | CL22: 1094 | CM22: 32 | CN22: 1 | CO22: 364 | CP22: 6 | CQ22: 157 | CR22: 1 | CT22: 3276 | CU22: 239 | CV22: 40 | CW22: 387 | CX22: 223 | CY22: 477 | CZ22: 11 | DA22: 23 | DB22: 1615 | DC22: 375 | DD22: 1180 | DE22: 112 | DF22: 496 | DG22: 582 | DH22: 573 | DI22: 481 | DJ22: 11 | DK22: 597 | DL22: 1395 | DM22: 87 | DN22: 2 | DO22: 740 | DP22: 475 | DQ22: 348 | DR22: 1030 | DS22: 14 | DT22: 27 | DU22: 7 | DV22: 208 | DW22: 15 | DX22: 260 | DY22: 553 | DZ22: 35 | EA22: 53 | EB22: 312 | EC22: 244 | ED22: 7533 | EE22: 328 | EF22: 1 | EG22: 292 | EI22: 79 | EJ22: 11810
A23: 106040962 | B23: 040962 | C23: BUTTE | D23: ENLOE MEDICAL CENTER- ESPLANADE | E23: 1531 ESPLANADE | F23: CHICO | G23: 95926 | H23: Non-profit Corporation (incl. Church-related) | I23: Small/Rural | J23: 200-299 | K23: District 4 | L23: District 3 | M23: Chapmantown/Chico | N23: Urban | O23: 18730 | Q23: 417 | S23: 497 | U23: 9049 | V23: 10594 | W23: 1 | X23: 2267 | Y23: 244 | Z23: 1482 | AA23: 1699 | AB23: 1135 | AC23: 1805 | AD23: 3348 | AE23: 3917 | AF23: 3747 | AH23: 2870 | AI23: 16106 | AJ23: 668 | AK23: 268 | AL23: 359 | AM23: 38 | AN23: 339 | AO23: 15007 | AP23: 366 | AQ23: 3061 | AR23: 206 | AS23: 16005 | AT23: 470 | AU23: 516 | AV23: 213 | AW23: 46 | AX23: 439 | AY23: 2 | BA23: 2 | BB23: 28 | BC23: 1923 | BE23: 13154 | BF23: 39 | BG23: 6451 | BI23: 86169 | BJ23: 12742 | BK23: 419 | BL23: 4203 | BM23: 1923 | BN23: 346 | BO23: 11 | BP23: 13103 | BQ23: 360 | BR23: 460 | BS23: 1867 | BT23: 105 | BU23: 3 | BW23: 558 | BX23: 2825 | CA23: 344 | CB23: 19 | CG23: 2174 | CH23: 17470 | CJ23: 9330 | CK23: 4476 | CL23: 5483 | CM23: 46 | CO23: 41 | CQ23: 268 | CT23: 1904 | CU23: 507 | CV23: 134 | CW23: 939 | CX23: 592 | CY23: 429 | CZ23: 16 | DA23: 14 | DB23: 3164 | DC23: 1343 | DD23: 1954 | DE23: 257 | DF23: 794 | DG23: 1072 | DH23: 2019 | DI23: 2010 | DJ23: 13 | DK23: 352 | DL23: 1965 | DM23: 166 | DO23: 1425 | DP23: 1907 | DQ23: 1607 | DR23: 1926 | DS23: 16 | DT23: 1 | DU23: 1 | DV23: 219 | DW23: 38 | DX23: 343 | DY23: 1446 | DZ23: 187 | EA23: 188 | EB23: 447 | EC23: 393 | ED23: 9288 | EE23: 212 | EF23: 3 | EG23: 402 | EH23: 3 | EI23: 99 | EJ23: 19137
A24: 106044006 | B24: 044006 | C24: BUTTE | D24: BUTTE COUNTY MENTAL HEALTH SERVICES | E24: 592 RIO LINDO AVE | F24: CHICO | G24: 95926 | H24: City or County | I24: Small/Rural | J24: 1-49 | K24: District 4 | L24: District 3 | M24: Chapmantown/Chico | N24: Urban | Q24: 273 | U24: 126 | V24: 147 | Y24: 13 | Z24: 69 | AA24: 72 | AB24: 57 | AC24: 46 | AD24: 12 | AG24: 4 | AH24: 53 | AI24: 208 | AJ24: 12 | AK24: 16 | AN24: 24 | AO24: 182 | AP24: 14 | AQ24: 37 | AS24: 72 | AT24: 54 | AU24: 131 | BA24: 16 | BF24: 132 | BG24: 141 | BI24: 1635 | BJ24: 1 | BK24: 271 | BL24: 1 | BP24: 257 | BT24: 8 | BU24: 5 | BV24: 2 | CD24: 1 | CH24: 273 | CJ24: 44 | CK24: 208 | CL24: 1 | CQ24: 20 | CX24: 271 | DN24: 2 | ED24: 273 | EG24: 6 | EI24: 1 | EJ24: 266
A25: 106050932 | B25: 050932 | C25: CALAVERAS | D25: MARK TWAIN MEDICAL CENTER | E25: 768 MOUNTAIN RANCH RD | F25: SAN ANDREAS | G25: 95249 | H25: Non-profit Corporation (incl. Church-related) | I25: Small/Rural | J25: 1-49 | K25: District 8 | L25: District 5 | M25: Angels Camp/Arnold/Copperopolis/Mountain Ranch/Murphys/San Andreas/Valley Springs/West Point | N25: Rural | O25: 767 | U25: 356 | V25: 411 | Z25: 16 | AA25: 37 | AB25: 36 | AC25: 92 | AD25: 185 | AE25: 204 | AF25: 193 | AG25: 4 | AH25: 37 | AI25: 725 | AJ25: 5 | AO25: 724 | AP25: 23 | AQ25: 20 | AS25: 763 | AU25: 1 | AX25: 3 | BE25: 727 | BF25: 1 | BG25: 39 | BI25: 2870 | BJ25: 722 | BL25: 45 | BP25: 318 | BQ25: 59 | BR25: 10 | BS25: 158 | BT25: 2 | BV25: 29 | BW25: 26 | BX25: 146 | CA25: 9 | CB25: 5 | CD25: 5 | CG25: 12 | CH25: 755 | CJ25: 528 | CK25: 129 | CL25: 79 | CM25: 2 | CO25: 17 | CP25: 2 | CQ25: 10 | CT25: 169 | CU25: 9 | CV25: 3 | CW25: 40 | CX25: 37 | CY25: 16 | DB25: 124 | DC25: 87 | DD25: 93 | DE25: 38 | DF25: 28 | DG25: 40 | DK25: 13 | DL25: 67 | DM25: 3 | DO25: 145 | DQ25: 56 | DR25: 48 | DV25: 1 | DW25: 1 | DX25: 17 | DY25: 51 | DZ25: 7 | EB25: 4 | ED25: 433 | EE25: 4 | EG25: 6 | EI25: 12 | EJ25: 749
A26: 106060870 | B26: 060870 | C26: COLUSA | D26: COLUSA MEDICAL CENTER | E26: 199 E WEBSTER ST | F26: COLUSA | G26: 95932 | H26: Investor - Limited Liability Company | I26: Small/Rural | J26: 1-49 | K26: District 4 | L26: District 3 | M26: Colusa | N26: Rural | O26: 538 | P26: 255 | U26: 364 | V26: 429 | Z26: 15 | AA26: 30 | AB26: 55 | AC26: 86 | AD26: 164 | AE26: 197 | AF26: 245 | AG26: 1 | AH26: 140 | AI26: 653 | AL26: 16 | AN26: 12 | AO26: 697 | AP26: 22 | AR26: 46 | AS26: 465 | AT26: 1 | AU26: 176 | AV26: 1 | AW26: 1 | AX26: 149 | BE26: 441 | BF26: 56 | BG26: 296 | BI26: 7822 | BJ26: 40 | BK26: 741 | BL26: 12 | BP26: 355 | BQ26: 64 | BS26: 275 | BV26: 34 | BW26: 29 | BX26: 30 | CA26: 5 | CB26: 1 | CG26: 282 | CH26: 511 | CJ26: 511 | CK26: 226 | CL26: 37 | CM26: 1 | CQ26: 12 | CR26: 6 | CT26: 291 | CU26: 4 | CV26: 5 | CW26: 41 | CX26: 18 | CY26: 25 | DB26: 91 | DC26: 100 | DD26: 36 | DE26: 29 | DF26: 21 | DG26: 46 | DK26: 33 | DL26: 45 | DM26: 7 | DN26: 1 | DO26: 509 | DQ26: 1 | DR26: 1 | DS26: 1 | DX26: 8 | DY26: 2 | EB26: 58 | EC26: 12 | ED26: 198 | EE26: 3 | EG26: 24 | EI26: 8 | EJ26: 761
A27: 106070924 | B27: 070924 | C27: CONTRA COSTA | D27: CONTRA COSTA REGIONAL MEDICAL CENTER | E27: 2500 ALHAMBRA AVE | F27: MARTINEZ | G27: 94553 | H27: City or County | I27: Small/Rural | J27: 150-199 | K27: District 3 | L27: District 14 | M27: Crockett/Hercules/Martinez West/Pinole/Port Costa/Richmond Northeast/Rodeo | N27: Urban | O27: 7581 | Q27: 712 | U27: 3302 | V27: 4991 | X27: 1882 | Y27: 170 | Z27: 1447 | AA27: 1523 | AB27: 750 | AC27: 863 | AD27: 848 | AE27: 500 | AF27: 310 | AH27: 3604 | AI27: 4123 | AJ27: 566 | AK27: 21 | AL27: 743 | AM27: 99 | AN27: 1183 | AO27: 2010 | AP27: 119 | AQ27: 3946 | AR27: 172 | AS27: 5135 | AT27: 636 | AU27: 305 | AV27: 30 | AX27: 353 | AY27: 1 | BA27: 2 | BB27: 14 | BC27: 1817 | BE27: 5676 | BF27: 300 | BG27: 2317 | BI27: 40854 | BJ27: 131 | BK27: 5676 | BL27: 655 | BM27: 1817 | BO27: 14 | BP27: 7314 | BQ27: 428 | BS27: 3 | BT27: 313 | BU27: 55 | BV27: 3 | BW27: 58 | BX27: 15 | BZ27: 8 | CA27: 15 | CB27: 81 | CG27: 241 | CH27: 8052 | CJ27: 1175 | CK27: 6642 | CL27: 284 | CM27: 4 | CO27: 29 | CQ27: 159 | CT27: 427 | CU27: 143 | CV27: 58 | CW27: 310 | CX27: 1007 | CY27: 122 | CZ27: 10 | DA27: 5 | DB27: 635 | DC27: 271 | DD27: 697 | DE27: 150 | DF27: 88 | DG27: 242 | DH27: 1938 | DI27: 1881 | DJ27: 1 | DK27: 104 | DL27: 179 | DM27: 15 | DN27: 10 | DO27: 2133 | DP27: 1679 | DQ27: 80 | DR27: 572 | DS27: 4 | DT27: 6 | DU27: 2 | DV27: 193 | DW27: 20 | DX27: 100 | DY27: 204 | DZ27: 39 | EA27: 30 | EB27: 26 | EC27: 29 | ED27: 2976 | EE27: 200 | EF27: 3 | EG27: 393 | EI27: 24 | EJ27: 7873
A28: 106070934 | B28: 070934 | C28: CONTRA COSTA | D28: SUTTER DELTA MEDICAL CENTER | E28: 3901 LONE TREE WAY | F28: ANTIOCH | G28: 94509 | H28: Non-profit Corporation (incl. Church-related) | I28: Small/Rural | J28: 100-149 | K28: District 7 | L28: District 11 | M28: Brentwood Central and West/Oakley | N28: Urban | O28: 6405 | U28: 2995 | V28: 3410 | X28: 449 | Y28: 60 | Z28: 405 | AA28: 635 | AB28: 505 | AC28: 972 | AD28: 1222 | AE28: 1104 | AF28: 1053 | AH28: 1517 | AI28: 4825 | AJ28: 63 | AK28: 17 | AL28: 393 | AM28: 296 | AN28: 1419 | AO28: 3065 | AP28: 54 | AQ28: 1064 | AR28: 97 | AS28: 5688 | AT28: 50 | AU28: 62 | AV28: 158 | AW28: 5 | AY28: 1 | AZ28: 1 | BA28: 2 | BB28: 1 | BC28: 437 | BE28: 5392 | BF28: 13 | BG28: 1000 | BI28: 25435 | BJ28: 4184 | BK28: 1538 | BL28: 246 | BM28: 437 | BP28: 3434 | BQ28: 274 | BR28: 4 | BS28: 657 | BT28: 69 | BU28: 1 | BV28: 245 | BW28: 181 | BX28: 1410 | BZ28: 1 | CA28: 113 | CB28: 13 | CD28: 3 | CG28: 236 | CH28: 6169 | CJ28: 2676 | CK28: 2110 | CL28: 1313 | CM28: 3 | CO28: 204 | CQ28: 94 | CR28: 5 | CT28: 1201 | CU28: 68 | CV28: 92 | CW28: 421 | CX28: 105 | CY28: 179 | CZ28: 2 | DA28: 3 | DB28: 1289 | DC28: 478 | DD28: 705 | DE28: 91 | DF28: 87 | DG28: 307 | DH28: 468 | DI28: 449 | DJ28: 2 | DK28: 117 | DL28: 331 | DM28: 10 | DO28: 941 | DP28: 431 | DQ28: 779 | DR28: 579 | DS28: 3 | DV28: 50 | DW28: 8 | DX28: 86 | DY28: 194 | DZ28: 33 | EA28: 17 | EB28: 100 | EC28: 78 | ED28: 2837 | EE28: 269 | EF28: 17 | EG28: 244 | EH28: 4 | EI28: 49 | EJ28: 6091
A29: 106070988 | B29: 070988 | C29: CONTRA COSTA | D29: JOHN MUIR MEDICAL CENTER-WALNUT CREEK CAMPUS | E29: 1601 YGNACIO VALLEY RD | F29: WALNUT CREEK | G29: 94598 | H29: Non-profit Corporation (incl. Church-related) | I29: Small/Rural | J29: 500+ | K29: District 7 | L29: District 16 | M29: Clayton/Concord South/Walnut Creek Central and East | N29: Urban | O29: 21538 | S29: 420 | U29: 9187 | V29: 12771 | X29: 3824 | Y29: 424 | Z29: 1256 | AA29: 3049 | AB29: 1183 | AC29: 1717 | AD29: 2752 | AE29: 3626 | AF29: 4127 | AH29: 3500 | AI29: 17555 | AJ29: 903 | AK29: 63 | AL29: 2444 | AM29: 172 | AN29: 1388 | AO29: 13711 | AP29: 888 | AQ29: 2500 | AR29: 792 | AS29: 15808 | AT29: 415 | AU29: 1908 | AV29: 771 | AW29: 6 | AX29: 25 | AY29: 5 | AZ29: 1 | BB29: 31 | BC29: 2988 | BE29: 11730 | BF29: 616 | BG29: 9612 | BI29: 117891 | BJ29: 11081 | BK29: 1158 | BL29: 5513 | BM29: 2988 | BN29: 1200 | BO29: 18 | BP29: 11682 | BQ29: 537 | BR29: 266 | BS29: 2586 | BT29: 11 | BU29: 14 | BV29: 188 | BW29: 697 | BX29: 5451 | BZ29: 39 | CA29: 366 | CB29: 107 | CD29: 6 | CE29: 8 | CG29: 1253 | CH29: 20705 | CJ29: 8743 | CK29: 3271 | CL29: 8736 | CM29: 149 | CO29: 537 | CQ29: 507 | CR29: 15 | CT29: 1739 | CU29: 987 | CV29: 147 | CW29: 633 | CX29: 201 | CY29: 476 | CZ29: 14 | DA29: 7 | DB29: 2182 | DC29: 1240 | DD29: 1722 | DE29: 259 | DF29: 1681 | DG29: 816 | DH29: 3213 | DI29: 3150 | DJ29: 27 | DK29: 214 | DL29: 3007 | DM29: 242 | DN29: 1 | DO29: 846 | DP29: 2941 | DQ29: 1072 | DR29: 1844 | DS29: 12 | DT29: 22 | DU29: 12 | DV29: 790 | DW29: 171 | DX29: 527 | DY29: 2661 | DZ29: 507 | EA29: 119 | EB29: 564 | EC29: 179 | ED29: 9138 | EE29: 553 | EF29: 25 | EG29: 291 | EH29: 4 | EI29: 136 | EJ29: 21502
A30: 106070990 | B30: 070990 | C30: CONTRA COSTA | D30: KAISER FOUNDATION HOSPITAL - WALNUT CREEK | E30: 1425 S MAIN ST | F30: WALNUT CREEK | G30: 94596 | H30: Non-profit Corporation (incl. Church-related) | I30: Small/Rural | J30: 200-299 | K30: District 7 | L30: District 16 | M30: Clayton/Concord South/Walnut Creek Central and East | N30: Urban | O30: 14977 | U30: 6042 | V30: 8935 | X30: 3308 | Y30: 120 | Z30: 867 | AA30: 2574 | AB30: 773 | AC30: 896 | AD30: 1523 | AE30: 2021 | AF30: 2895 | AH30: 2051 | AI30: 12633 | AJ30: 293 | AK30: 34 | AL30: 2854 | AM30: 64 | AN30: 790 | AO30: 8570 | AP30: 237 | AQ30: 2201 | AR30: 227 | AS30: 10115 | AT30: 273 | AU30: 564 | AV30: 430 | AW30: 483 | AX30: 1 | AY30: 1 | BB30: 46 | BC30: 3064 | BE30: 7517 | BF30: 256 | BG30: 7204 | BI30: 57707 | BJ30: 1770 | BK30: 9263 | BL30: 867 | BM30: 3064 | BO30: 13 | BP30: 10256 | BQ30: 325 | BR30: 56 | BS30: 1373 | BT30: 5 | BV30: 88 | BW30: 361 | BX30: 2136 | CA30: 318 | CB30: 11 | CD30: 11 | CE30: 37 | CG30: 1934 | CH30: 13043 | CJ30: 5686 | CK30: 780 | CL30: 8402 | CM30: 5 | CO30: 11 | CQ30: 92 | CR30: 1 | CT30: 1843 | CU30: 326 | CV30: 95 | CW30: 345 | CX30: 147 | CY30: 230 | CZ30: 14 | DA30: 4 | DB30: 1776 | DC30: 701 | DD30: 1137 | DE30: 200 | DF30: 139 | DG30: 481 | DH30: 3244 | DI30: 3132 | DJ30: 6 | DK30: 244 | DL30: 853 | DM30: 60 | DO30: 3815 | DP30: 3077 | DQ30: 1114 | DR30: 1174 | DS30: 6 | DT30: 3 | DU30: 4 | DV30: 870 | DW30: 27 | DX30: 216 | DY30: 610 | DZ30: 83 | EA30: 90 | EB30: 212 | EC30: 279 | ED30: 3078 | EE30: 319 | EG30: 38 | EI30: 36 | EJ30: 14903
A31: 106071018 | B31: 071018 | C31: CONTRA COSTA | D31: JOHN MUIR MEDICAL CENTER-CONCORD CAMPUS | E31: 2540 EAST ST | F31: CONCORD | G31: 94520 | H31: Non-profit Corporation (incl. Church-related) | I31: Small/Rural | J31: 200-299 | K31: District 7 | L31: District 14 | M31: Avon/Clyde/Concord Central/Pittsburg Southwest | N31: Urban | O31: 10777 | U31: 5560 | V31: 5217 | Y31: 31 | Z31: 276 | AA31: 518 | AB31: 867 | AC31: 1485 | AD31: 2550 | AE31: 2684 | AF31: 2366 | AH31: 1926 | AI31: 8727 | AJ31: 124 | AK31: 34 | AL31: 923 | AM31: 120 | AN31: 1275 | AO31: 6708 | AP31: 131 | AQ31: 1442 | AR31: 144 | AS31: 9519 | AT31: 262 | AU31: 600 | AV31: 369 | AW31: 10 | AX31: 5 | AY31: 3 | AZ31: 1 | BA31: 3 | BB31: 5 | BE31: 8297 | BF31: 88 | BG31: 2392 | BI31: 60503 | BJ31: 8338 | BK31: 871 | BL31: 1565 | BN31: 1 | BO31: 2 | BP31: 4320 | BQ31: 243 | BR31: 50 | BS31: 1572 | BT31: 3 | BU31: 7 | BV31: 313 | BW31: 424 | BX31: 3575 | CA31: 209 | CB31: 55 | CE31: 6 | CG31: 695 | CH31: 10082 | CJ31: 5921 | CK31: 2260 | CL31: 1836 | CM31: 13 | CN31: 1 | CO31: 551 | CQ31: 179 | CR31: 16 | CT31: 1528 | CU31: 530 | CV31: 99 | CW31: 861 | CX31: 172 | CY31: 239 | CZ31: 9 | DA31: 12 | DB31: 2591 | DC31: 715 | DD31: 1326 | DE31: 174 | DF31: 651 | DG31: 826 | DH31: 12 | DJ31: 36 | DK31: 134 | DL31: 827 | DM31: 35 | DO31: 563 | DQ31: 2137 | DR31: 1445 | DS31: 3 | DT31: 4 | DV31: 88 | DW31: 72 | DX31: 190 | DY31: 1008 | DZ31: 51 | EA31: 16 | EB31: 427 | EC31: 316 | ED31: 3995 | EE31: 462 | EF31: 2 | EG31: 317 | EH31: 3 | EI31: 66 | EJ31: 10389
A32: 106074017 | B32: 074017 | C32: CONTRA COSTA | D32: SAN RAMON REGIONAL MEDICAL CENTER | E32: 6001 NORRIS CANYON RD | F32: SAN RAMON | G32: 94583 | H32: Investor - Corporation | I32: Small/Rural | J32: 100-149 | K32: District 7 | L32: District 16 | M32: Alamo/Danville/Diablo/San Ramon | N32: Urban | O32: 3842 | U32: 1683 | V32: 2159 | X32: 260 | Y32: 20 | Z32: 103 | AA32: 323 | AB32: 286 | AC32: 356 | AD32: 562 | AE32: 852 | AF32: 1080 | AH32: 207 | AI32: 3453 | AJ32: 182 | AL32: 598 | AM32: 28 | AN32: 170 | AO32: 2475 | AP32: 112 | AQ32: 443 | AR32: 16 | AS32: 3546 | AT32: 17 | AU32: 5 | AV32: 7 | AW32: 14 | AX32: 4 | AY32: 1 | AZ32: 1 | BC32: 247 | BE32: 2854 | BF32: 3 | BG32: 985 | BI32: 17484 | BJ32: 1342 | BK32: 1707 | BL32: 546 | BM32: 247 | BP32: 2222 | BQ32: 54 | BR32: 6 | BS32: 476 | BT32: 18 | BU32: 1 | BV32: 61 | BW32: 86 | BX32: 810 | BZ32: 3 | CA32: 102 | CB32: 3 | CG32: 466 | CH32: 3373 | CI32: 3 | CJ32: 1916 | CK32: 176 | CL32: 1379 | CM32: 81 | CO32: 13 | CP32: 2 | CQ32: 4 | CR32: 271 | CT32: 427 | CU32: 106 | CV32: 30 | CW32: 209 | CX32: 64 | CY32: 121 | CZ32: 2 | DA32: 8 | DB32: 609 | DC32: 258 | DD32: 516 | DE32: 65 | DF32: 337 | DG32: 162 | DH32: 259 | DI32: 251 | DJ32: 3 | DK32: 97 | DL32: 298 | DM32: 20 | DO32: 988 | DP32: 245 | DQ32: 286 | DR32: 454 | DS32: 2 | DV32: 22 | DW32: 4 | DX32: 49 | DY32: 432 | DZ32: 56 | EA32: 6 | EB32: 95 | EC32: 84 | ED32: 1011 | EE32: 108 | EF32: 8 | EG32: 1 | EI32: 52 | EJ32: 3781
A33: 106074039 | B33: 074039 | C33: CONTRA COSTA | D33: JOHN MUIR BEHAVIORAL HEALTH CENTER | E33: 2740 GRANT ST | F33: CONCORD | G33: 94520 | H33: Non-profit Corporation (incl. Church-related) | I33: Small/Rural | J33: 50-99 | K33: District 7 | L33: District 14 | M33: Concord West/Martinez East/Martinez Waterfront/Pacheco/Pleasant Hill East | N33: Urban | Q33: 3101 | U33: 1215 | V33: 1886 | X33: 46 | Y33: 1571 | Z33: 442 | AA33: 285 | AB33: 210 | AC33: 224 | AD33: 218 | AE33: 95 | AG33: 10 | AH33: 601 | AI33: 2353 | AJ33: 147 | AK33: 19 | AL33: 230 | AM33: 16 | AN33: 292 | AO33: 1559 | AP33: 149 | AQ33: 777 | AR33: 59 | AS33: 526 | AT33: 1 | AU33: 2573 | BB33: 1 | BF33: 2471 | BG33: 630 | BI33: 18300 | BJ33: 2692 | BK33: 404 | BL33: 3 | BO33: 2 | BP33: 2675 | BQ33: 48 | BR33: 24 | BS33: 3 | BU33: 2 | BV33: 335 | CB33: 10 | CD33: 1 | CE33: 3 | CH33: 3101 | CJ33: 412 | CK33: 751 | CL33: 1644 | CO33: 237 | CQ33: 57 | CX33: 3092 | CY33: 2 | DN33: 7 | ED33: 3099 | EE33: 2 | EF33: 2 | EG33: 91 | EI33: 28 | EJ33: 2980
A34: 106074097 | B34: 074097 | C34: CONTRA COSTA | D34: KAISER FOUNDATION HOSPITAL - ANTIOCH | E34: 4501 SAND CREEK ROAD | F34: ANTIOCH | G34: 94531 | H34: Non-profit Corporation (incl. Church-related) | I34: Small/Rural | J34: 150-199 | K34: District 7 | L34: District 11 | M34: Brentwood Central and West/Oakley | N34: Urban | O34: 10532 | U34: 4217 | V34: 6315 | X34: 1880 | Y34: 67 | Z34: 940 | AA34: 1432 | AB34: 643 | AC34: 998 | AD34: 1325 | AE34: 1722 | AF34: 1524 | AG34: 1 | AH34: 2414 | AI34: 8058 | AJ34: 60 | AK34: 28 | AL34: 1242 | AM34: 91 | AN34: 1716 | AO34: 4783 | AP34: 54 | AQ34: 2493 | AR34: 125 | AS34: 8093 | AT34: 116 | AU34: 252 | AV34: 69 | AW34: 156 | BB34: 12 | BC34: 1834 | BE34: 5920 | BF34: 29 | BG34: 4583 | BI34: 37175 | BJ34: 1388 | BK34: 6686 | BL34: 623 | BM34: 1834 | BO34: 1 | BP34: 6858 | BQ34: 358 | BR34: 30 | BS34: 648 | BV34: 98 | BW34: 239 | BX34: 2094 | CA34: 173 | CB34: 4 | CD34: 4 | CE34: 25 | CF34: 1 | CG34: 912 | CH34: 9620 | CJ34: 4126 | CK34: 1206 | CL34: 5078 | CM34: 11 | CO34: 7 | CQ34: 104 | CT34: 1895 | CU34: 266 | CV34: 88 | CW34: 247 | CX34: 74 | CY34: 173 | CZ34: 2 | DA34: 4 | DB34: 1231 | DC34: 466 | DD34: 972 | DE34: 111 | DF34: 146 | DG34: 330 | DH34: 1963 | DI34: 1878 | DJ34: 8 | DK34: 147 | DL34: 493 | DM34: 38 | DO34: 2732 | DP34: 1849 | DQ34: 390 | DR34: 992 | DS34: 6 | DT34: 1 | DV34: 538 | DW34: 18 | DX34: 168 | DY34: 418 | DZ34: 54 | EA34: 39 | EB34: 167 | EC34: 238 | ED34: 2624 | EE34: 298 | EF34: 3 | EG34: 61 | EI34: 15 | EJ34: 10453
A35: 106084001 | B35: 084001 | C35: DEL NORTE | D35: SUTTER COAST HOSPITAL | E35: 800 E WASHINGTON BLVD | F35: CRESCENT CITY | G35: 95531 | H35: Non-profit Corporation (incl. Church-related) | I35: Small/Rural | J35: 1-49 | K35: District 2 | L35: District 2 | M35: Crescent City/Gasquet/Klamath/Smith River | N35: Rural | O35: 2188 | S35: 139 | U35: 1025 | V35: 1302 | X35: 285 | Y35: 49 | Z35: 198 | AA35: 198 | AB35: 122 | AC35: 255 | AD35: 430 | AE35: 459 | AF35: 331 | AH35: 212 | AI35: 2067 | AJ35: 48 | AK35: 96 | AL35: 43 | AM35: 12 | AN35: 18 | AO35: 1931 | AP35: 22 | AQ35: 124 | AR35: 81 | AS35: 1848 | AT35: 16 | AU35: 87 | AV35: 45 | AW35: 1 | AX35: 64 | AY35: 1 | BA35: 20 | BC35: 245 | BE35: 1565 | BF35: 6 | BG35: 756 | BI35: 10163 | BJ35: 914 | BK35: 722 | BL35: 397 | BM35: 245 | BN35: 49 | BP35: 1517 | BQ35: 108 | BR35: 57 | BS35: 145 | BT35: 4 | BU35: 24 | BV35: 77 | BW35: 83 | BX35: 304 | CA35: 4 | CB35: 1 | CD35: 3 | CG35: 194 | CH35: 2133 | CJ35: 1035 | CK35: 697 | CL35: 305 | CM35: 10 | CO35: 214 | CQ35: 66 | CT35: 567 | CU35: 21 | CV35: 22 | CW35: 80 | CX35: 31 | CY35: 41 | DB35: 273 | DC35: 115 | DD35: 205 | DE35: 48 | DF35: 70 | DG35: 54 | DH35: 258 | DI35: 252 | DK35: 25 | DL35: 231 | DM35: 34 | DO35: 308 | DP35: 240 | DQ35: 23 | DR35: 151 | DV35: 43 | DW35: 3 | DX35: 60 | DY35: 219 | DZ35: 5 | EA35: 8 | EB35: 40 | EC35: 5 | ED35: 1170 | EE35: 52 | EF35: 6 | EG35: 46 | EI35: 326 | EJ35: 1949
A36: 106090793 | B36: 090793 | C36: EL DORADO | D36: BARTON MEMORIAL HOSPITAL | E36: 2170 SOUTH AVE | F36: SOUTH LAKE TAHOE | G36: 96150 | H36: Non-profit Corporation (incl. Church-related) | I36: Small/Rural | J36: 100-149 | K36: District 1 | L36: District 5 | M36: South Lake Tahoe | N36: Rural | O36: 1914 | P36: 6 | U36: 895 | V36: 1025 | X36: 367 | Y36: 29 | Z36: 140 | AA36: 271 | AB36: 139 | AC36: 185 | AD36: 312 | AE36: 295 | AF36: 182 | AH36: 306 | AI36: 1507 | AJ36: 107 | AL36: 46 | AN36: 21 | AO36: 1633 | AP36: 116 | AQ36: 80 | AR36: 24 | AS36: 1200 | AT36: 405 | AU36: 10 | AV36: 5 | AX36: 6 | BA36: 4 | BB36: 1 | BC36: 289 | BE36: 1174 | BG36: 746 | BI36: 7089 | BJ36: 1090 | BK36: 48 | BL36: 418 | BM36: 289 | BN36: 75 | BP36: 1576 | BQ36: 57 | BR36: 12 | BS36: 102 | BT36: 3 | BU36: 2 | BV36: 19 | BW36: 43 | BX36: 70 | BZ36: 10 | CA36: 8 | CB36: 10 | CC36: 8 | CG36: 136 | CH36: 1784 | CJ36: 635 | CK36: 512 | CL36: 600 | CM36: 5 | CO36: 91 | CQ36: 67 | CR36: 10 | CT36: 180 | CU36: 26 | CV36: 10 | CW36: 52 | CX36: 61 | CY36: 17 | DA36: 1 | DB36: 116 | DC36: 183 | DD36: 227 | DE36: 40 | DF36: 112 | DG36: 40 | DH36: 302 | DI36: 307 | DK36: 19 | DL36: 217 | DM36: 10 | DO36: 375 | DP36: 286 | DQ36: 24 | DR36: 152 | DS36: 1 | DT36: 1 | DV36: 23 | DX36: 35 | DY36: 218 | DZ36: 13 | EA36: 8 | EB36: 28 | EC36: 7 | ED36: 722 | EE36: 27 | EF36: 1 | EG36: 24 | EH36: 4 | EI36: 341 | EJ36: 1550
A37: 106090933 | B37: 090933 | C37: EL DORADO | D37: MARSHALL MEDICAL CENTER | E37: 1100 MARSHALL WAY | F37: PLACERVILLE | G37: 95667 | H37: Non-profit Corporation (incl. Church-related) | I37: Small/Rural | J37: 100-149 | K37: District 1 | L37: District 5 | M37: Cool/Diamond Springs/Latrobe/Pilot Hill/Placerville | N37: Rural | O37: 4691 | U37: 2199 | V37: 2492 | X37: 366 | Y37: 26 | Z37: 297 | AA37: 364 | AB37: 280 | AC37: 460 | AD37: 867 | AE37: 1007 | AF37: 1023 | AG37: 1 | AH37: 353 | AI37: 4279 | AJ37: 59 | AK37: 32 | AL37: 24 | AN37: 25 | AO37: 4118 | AP37: 72 | AQ37: 394 | AR37: 26 | AS37: 3714 | AT37: 547 | AU37: 13 | AV37: 42 | AW37: 10 | BA37: 2 | BB37: 15 | BC37: 348 | BE37: 3741 | BF37: 2 | BG37: 941 | BH37: 7 | BI37: 18143 | BJ37: 2451 | BK37: 1328 | BL37: 429 | BM37: 348 | BN37: 134 | BO37: 1 | BP37: 3025 | BQ37: 174 | BR37: 5 | BS37: 574 | BT37: 10 | BU37: 14 | BV37: 77 | BW37: 131 | BX37: 507 | CA37: 162 | CB37: 4 | CC37: 1 | CD37: 7 | CG37: 435 | CH37: 4256 | CJ37: 1856 | CK37: 1234 | CL37: 1375 | CM37: 10 | CO37: 163 | CQ37: 32 | CR37: 7 | CS37: 14 | CT37: 701 | CU37: 95 | CV37: 14 | CW37: 193 | CX37: 153 | CY37: 74 | CZ37: 3 | DA37: 4 | DB37: 663 | DC37: 462 | DD37: 606 | DE37: 102 | DF37: 177 | DG37: 211 | DH37: 385 | DI37: 366 | DJ37: 1 | DK37: 48 | DL37: 423 | DM37: 8 | DN37: 2 | DO37: 953 | DP37: 344 | DQ37: 217 | DR37: 418 | DS37: 1 | DU37: 1 | DV37: 21 | DW37: 2 | DX37: 100 | DY37: 306 | DZ37: 21 | EA37: 8 | EB37: 85 | EC37: 276 | ED37: 1876 | EE37: 62 | EG37: 123 | EH37: 1 | EI37: 19 | EJ37: 4548
